<?xml version="1.0" encoding="UTF-8"?><testsuite name="nosetests" tests="3" errors="1" failures="1" skip="0"><testcase classname="src.tests.test_prod" name="test_factorial_succeeding" time="0.014"></testcase><testcase classname="src.tests.test_prod" name="test_factorial_failing" time="0.000"><failure type="exceptions.AssertionError" message=""><![CDATA[Traceback (most recent call last):
  File "/usr/lib/python2.7/unittest/case.py", line 331, in run
    testMethod()
  File "/usr/lib/python2.7/dist-packages/nose/case.py", line 197, in runTest
    self.test(*self.arg)
  File "/home/wenns/src/sonar-python/sonar-python-plugin/src/test/resources/org/sonar/plugins/python/smoketest_project_1/src/tests/test_prod.py", line 6, in test_factorial_failing
    assert factorial(3) == 2
AssertionError
]]></failure></testcase><testcase classname="src.tests.test_prod" name="test_factorial_error" time="0.000"><error type="exceptions.RuntimeError" message=""><![CDATA[Traceback (most recent call last):
  File "/usr/lib/python2.7/unittest/case.py", line 331, in run
    testMethod()
  File "/usr/lib/python2.7/dist-packages/nose/case.py", line 197, in runTest
    self.test(*self.arg)
  File "/home/wenns/src/sonar-python/sonar-python-plugin/src/test/resources/org/sonar/plugins/python/smoketest_project_1/src/tests/test_prod.py", line 10, in test_factorial_error
    raise RuntimeError()
RuntimeError
]]></error></testcase></testsuite>